

Exception type : ProgrammingError 
Exception message : 1045 (28000): Access denied for user 'root'@'localhost' (using password: NO)
Stack trace : ['File : /Users/lql4/PycharmProjects/flaskUtil/util/mysqlUtil.py , Line : 67, Func.Name : getDB, Message : db = mysql.connector.connect(host=host, user=user, password=password, database=database)', 'File : /Users/lql4/opt/anaconda3/lib/python3.9/site-packages/mysql/connector/__init__.py , Line : 273, Func.Name : connect, Message : return MySQLConnection(*args, **kwargs)', 'File : /Users/lql4/opt/anaconda3/lib/python3.9/site-packages/mysql/connector/connection.py , Line : 116, Func.Name : __init__, Message : self.connect(**kwargs)', 'File : /Users/lql4/opt/anaconda3/lib/python3.9/site-packages/mysql/connector/abstracts.py , Line : 1052, Func.Name : connect, Message : self._open_connection()', 'File : /Users/lql4/opt/anaconda3/lib/python3.9/site-packages/mysql/connector/connection.py , Line : 496, Func.Name : _open_connection, Message : self._do_auth(self._user, self._password,', 'File : /Users/lql4/opt/anaconda3/lib/python3.9/site-packages/mysql/connector/connection.py , Line : 242, Func.Name : _do_auth, Message : self._auth_switch_request(username, password)', 'File : /Users/lql4/opt/anaconda3/lib/python3.9/site-packages/mysql/connector/connection.py , Line : 288, Func.Name : _auth_switch_request, Message : raise errors.get_exception(packet)']
sql operation : fail to connect to sql

Exception type : ProgrammingError 
Exception message : 1045 (28000): Access denied for user 'root'@'localhost' (using password: YES)
Stack trace : ['File : /Users/lql4/PycharmProjects/flaskUtil/util/mysqlUtil.py , Line : 67, Func.Name : getDB, Message : db = mysql.connector.connect(host=host, user=user, password=password, database=database)', 'File : /Users/lql4/opt/anaconda3/lib/python3.9/site-packages/mysql/connector/__init__.py , Line : 273, Func.Name : connect, Message : return MySQLConnection(*args, **kwargs)', 'File : /Users/lql4/opt/anaconda3/lib/python3.9/site-packages/mysql/connector/connection.py , Line : 116, Func.Name : __init__, Message : self.connect(**kwargs)', 'File : /Users/lql4/opt/anaconda3/lib/python3.9/site-packages/mysql/connector/abstracts.py , Line : 1052, Func.Name : connect, Message : self._open_connection()', 'File : /Users/lql4/opt/anaconda3/lib/python3.9/site-packages/mysql/connector/connection.py , Line : 496, Func.Name : _open_connection, Message : self._do_auth(self._user, self._password,', 'File : /Users/lql4/opt/anaconda3/lib/python3.9/site-packages/mysql/connector/connection.py , Line : 242, Func.Name : _do_auth, Message : self._auth_switch_request(username, password)', 'File : /Users/lql4/opt/anaconda3/lib/python3.9/site-packages/mysql/connector/connection.py , Line : 288, Func.Name : _auth_switch_request, Message : raise errors.get_exception(packet)']
sql operation : fail to connect to sql

Exception type : ProgrammingError 
Exception message : 1049 (42000): Unknown database 'envtestdatabase'
Stack trace : ['File : /Users/lql4/PycharmProjects/flaskUtil/util/mysqlUtil.py , Line : 67, Func.Name : getDB, Message : db = mysql.connector.connect(host=host, user=user, password="?Aa13552676625", database=database)', 'File : /Users/lql4/opt/anaconda3/lib/python3.9/site-packages/mysql/connector/__init__.py , Line : 273, Func.Name : connect, Message : return MySQLConnection(*args, **kwargs)', 'File : /Users/lql4/opt/anaconda3/lib/python3.9/site-packages/mysql/connector/connection.py , Line : 116, Func.Name : __init__, Message : self.connect(**kwargs)', 'File : /Users/lql4/opt/anaconda3/lib/python3.9/site-packages/mysql/connector/abstracts.py , Line : 1052, Func.Name : connect, Message : self._open_connection()', 'File : /Users/lql4/opt/anaconda3/lib/python3.9/site-packages/mysql/connector/connection.py , Line : 496, Func.Name : _open_connection, Message : self._do_auth(self._user, self._password,', 'File : /Users/lql4/opt/anaconda3/lib/python3.9/site-packages/mysql/connector/connection.py , Line : 242, Func.Name : _do_auth, Message : self._auth_switch_request(username, password)', 'File : /Users/lql4/opt/anaconda3/lib/python3.9/site-packages/mysql/connector/connection.py , Line : 288, Func.Name : _auth_switch_request, Message : raise errors.get_exception(packet)']
sql operation : fail to connect to sql

Exception type : ProgrammingError 
Exception message : 1049 (42000): Unknown database 'envtestdatabase'
Stack trace : ['File : /Users/lql4/PycharmProjects/flaskUtil/util/mysqlUtil.py , Line : 67, Func.Name : getDB, Message : db = mysql.connector.connect(host=host, user=user, password=password, database=database)', 'File : /Users/lql4/opt/anaconda3/lib/python3.9/site-packages/mysql/connector/__init__.py , Line : 273, Func.Name : connect, Message : return MySQLConnection(*args, **kwargs)', 'File : /Users/lql4/opt/anaconda3/lib/python3.9/site-packages/mysql/connector/connection.py , Line : 116, Func.Name : __init__, Message : self.connect(**kwargs)', 'File : /Users/lql4/opt/anaconda3/lib/python3.9/site-packages/mysql/connector/abstracts.py , Line : 1052, Func.Name : connect, Message : self._open_connection()', 'File : /Users/lql4/opt/anaconda3/lib/python3.9/site-packages/mysql/connector/connection.py , Line : 496, Func.Name : _open_connection, Message : self._do_auth(self._user, self._password,', 'File : /Users/lql4/opt/anaconda3/lib/python3.9/site-packages/mysql/connector/connection.py , Line : 242, Func.Name : _do_auth, Message : self._auth_switch_request(username, password)', 'File : /Users/lql4/opt/anaconda3/lib/python3.9/site-packages/mysql/connector/connection.py , Line : 288, Func.Name : _auth_switch_request, Message : raise errors.get_exception(packet)']
sql operation : fail to connect to sql

Exception type : ProgrammingError 
Exception message : 1049 (42000): Unknown database 'envtestdatabase'
Stack trace : ['File : /Users/lql4/PycharmProjects/flaskUtil/util/mysqlUtil.py , Line : 67, Func.Name : getDB, Message : db = mysql.connector.connect(host=host, user=user, password=password, database=database)', 'File : /Users/lql4/opt/anaconda3/lib/python3.9/site-packages/mysql/connector/__init__.py , Line : 273, Func.Name : connect, Message : return MySQLConnection(*args, **kwargs)', 'File : /Users/lql4/opt/anaconda3/lib/python3.9/site-packages/mysql/connector/connection.py , Line : 116, Func.Name : __init__, Message : self.connect(**kwargs)', 'File : /Users/lql4/opt/anaconda3/lib/python3.9/site-packages/mysql/connector/abstracts.py , Line : 1052, Func.Name : connect, Message : self._open_connection()', 'File : /Users/lql4/opt/anaconda3/lib/python3.9/site-packages/mysql/connector/connection.py , Line : 496, Func.Name : _open_connection, Message : self._do_auth(self._user, self._password,', 'File : /Users/lql4/opt/anaconda3/lib/python3.9/site-packages/mysql/connector/connection.py , Line : 242, Func.Name : _do_auth, Message : self._auth_switch_request(username, password)', 'File : /Users/lql4/opt/anaconda3/lib/python3.9/site-packages/mysql/connector/connection.py , Line : 288, Func.Name : _auth_switch_request, Message : raise errors.get_exception(packet)']
sql operation : fail to connect to sql

Exception type : ProgrammingError 
Exception message : 1045 (28000): Access denied for user 'root'@'localhost' (using password: YES)
Stack trace : ['File : /Users/lql4/PycharmProjects/flaskUtil/util/mysqlUtil.py , Line : 67, Func.Name : getDB, Message : db = mysql.connector.connect(host=host, user=user, password=password, database=database)', 'File : /Users/lql4/opt/anaconda3/lib/python3.9/site-packages/mysql/connector/__init__.py , Line : 273, Func.Name : connect, Message : return MySQLConnection(*args, **kwargs)', 'File : /Users/lql4/opt/anaconda3/lib/python3.9/site-packages/mysql/connector/connection.py , Line : 116, Func.Name : __init__, Message : self.connect(**kwargs)', 'File : /Users/lql4/opt/anaconda3/lib/python3.9/site-packages/mysql/connector/abstracts.py , Line : 1052, Func.Name : connect, Message : self._open_connection()', 'File : /Users/lql4/opt/anaconda3/lib/python3.9/site-packages/mysql/connector/connection.py , Line : 496, Func.Name : _open_connection, Message : self._do_auth(self._user, self._password,', 'File : /Users/lql4/opt/anaconda3/lib/python3.9/site-packages/mysql/connector/connection.py , Line : 242, Func.Name : _do_auth, Message : self._auth_switch_request(username, password)', 'File : /Users/lql4/opt/anaconda3/lib/python3.9/site-packages/mysql/connector/connection.py , Line : 288, Func.Name : _auth_switch_request, Message : raise errors.get_exception(packet)']
sql operation : fail to connect to sql

Exception type : ProgrammingError 
Exception message : 1045 (28000): Access denied for user 'root'@'localhost' (using password: YES)
Stack trace : ['File : /Users/lql4/PycharmProjects/flaskUtil/util/mysqlUtil.py , Line : 67, Func.Name : getDB, Message : db = mysql.connector.connect(host=host, user=user, password=password, database=database)', 'File : /Users/lql4/opt/anaconda3/lib/python3.9/site-packages/mysql/connector/__init__.py , Line : 273, Func.Name : connect, Message : return MySQLConnection(*args, **kwargs)', 'File : /Users/lql4/opt/anaconda3/lib/python3.9/site-packages/mysql/connector/connection.py , Line : 116, Func.Name : __init__, Message : self.connect(**kwargs)', 'File : /Users/lql4/opt/anaconda3/lib/python3.9/site-packages/mysql/connector/abstracts.py , Line : 1052, Func.Name : connect, Message : self._open_connection()', 'File : /Users/lql4/opt/anaconda3/lib/python3.9/site-packages/mysql/connector/connection.py , Line : 496, Func.Name : _open_connection, Message : self._do_auth(self._user, self._password,', 'File : /Users/lql4/opt/anaconda3/lib/python3.9/site-packages/mysql/connector/connection.py , Line : 242, Func.Name : _do_auth, Message : self._auth_switch_request(username, password)', 'File : /Users/lql4/opt/anaconda3/lib/python3.9/site-packages/mysql/connector/connection.py , Line : 288, Func.Name : _auth_switch_request, Message : raise errors.get_exception(packet)']
sql operation : fail to connect to sql

Exception type : ProgrammingError 
Exception message : 1049 (42000): Unknown database 'envtestdatabase'
Stack trace : ['File : /Users/lql4/PycharmProjects/flaskUtil/util/mysqlUtil.py , Line : 67, Func.Name : getDB, Message : db = mysql.connector.connect(host=host, user=user, password=password, database=database)', 'File : /Users/lql4/opt/anaconda3/lib/python3.9/site-packages/mysql/connector/__init__.py , Line : 273, Func.Name : connect, Message : return MySQLConnection(*args, **kwargs)', 'File : /Users/lql4/opt/anaconda3/lib/python3.9/site-packages/mysql/connector/connection.py , Line : 116, Func.Name : __init__, Message : self.connect(**kwargs)', 'File : /Users/lql4/opt/anaconda3/lib/python3.9/site-packages/mysql/connector/abstracts.py , Line : 1052, Func.Name : connect, Message : self._open_connection()', 'File : /Users/lql4/opt/anaconda3/lib/python3.9/site-packages/mysql/connector/connection.py , Line : 496, Func.Name : _open_connection, Message : self._do_auth(self._user, self._password,', 'File : /Users/lql4/opt/anaconda3/lib/python3.9/site-packages/mysql/connector/connection.py , Line : 242, Func.Name : _do_auth, Message : self._auth_switch_request(username, password)', 'File : /Users/lql4/opt/anaconda3/lib/python3.9/site-packages/mysql/connector/connection.py , Line : 288, Func.Name : _auth_switch_request, Message : raise errors.get_exception(packet)']
sql operation : fail to connect to sql

Exception type : ProgrammingError 
Exception message : 1049 (42000): Unknown database 'envtestdatabase'
Stack trace : ['File : /Users/lql4/PycharmProjects/flaskUtil/util/mysqlUtil.py , Line : 67, Func.Name : getDB, Message : db = mysql.connector.connect(host=host, user=user, password=password, database=database)', 'File : /Users/lql4/opt/anaconda3/lib/python3.9/site-packages/mysql/connector/__init__.py , Line : 273, Func.Name : connect, Message : return MySQLConnection(*args, **kwargs)', 'File : /Users/lql4/opt/anaconda3/lib/python3.9/site-packages/mysql/connector/connection.py , Line : 116, Func.Name : __init__, Message : self.connect(**kwargs)', 'File : /Users/lql4/opt/anaconda3/lib/python3.9/site-packages/mysql/connector/abstracts.py , Line : 1052, Func.Name : connect, Message : self._open_connection()', 'File : /Users/lql4/opt/anaconda3/lib/python3.9/site-packages/mysql/connector/connection.py , Line : 496, Func.Name : _open_connection, Message : self._do_auth(self._user, self._password,', 'File : /Users/lql4/opt/anaconda3/lib/python3.9/site-packages/mysql/connector/connection.py , Line : 242, Func.Name : _do_auth, Message : self._auth_switch_request(username, password)', 'File : /Users/lql4/opt/anaconda3/lib/python3.9/site-packages/mysql/connector/connection.py , Line : 288, Func.Name : _auth_switch_request, Message : raise errors.get_exception(packet)']
sql operation : fail to connect to sql

Exception type : ProgrammingError 
Exception message : 1049 (42000): Unknown database 'envtestdatabase'
Stack trace : ['File : /Users/lql4/PycharmProjects/flaskUtil/util/mysqlUtil.py , Line : 67, Func.Name : getDB, Message : db = mysql.connector.connect(host=host, user=user, password=password, database=database)', 'File : /Users/lql4/opt/anaconda3/lib/python3.9/site-packages/mysql/connector/__init__.py , Line : 273, Func.Name : connect, Message : return MySQLConnection(*args, **kwargs)', 'File : /Users/lql4/opt/anaconda3/lib/python3.9/site-packages/mysql/connector/connection.py , Line : 116, Func.Name : __init__, Message : self.connect(**kwargs)', 'File : /Users/lql4/opt/anaconda3/lib/python3.9/site-packages/mysql/connector/abstracts.py , Line : 1052, Func.Name : connect, Message : self._open_connection()', 'File : /Users/lql4/opt/anaconda3/lib/python3.9/site-packages/mysql/connector/connection.py , Line : 496, Func.Name : _open_connection, Message : self._do_auth(self._user, self._password,', 'File : /Users/lql4/opt/anaconda3/lib/python3.9/site-packages/mysql/connector/connection.py , Line : 242, Func.Name : _do_auth, Message : self._auth_switch_request(username, password)', 'File : /Users/lql4/opt/anaconda3/lib/python3.9/site-packages/mysql/connector/connection.py , Line : 288, Func.Name : _auth_switch_request, Message : raise errors.get_exception(packet)']
sql operation : fail to connect to sql

Exception type : ProgrammingError 
Exception message : 1049 (42000): Unknown database 'envtestdatabase'
Stack trace : ['File : /Users/lql4/PycharmProjects/flaskUtil/util/mysqlUtil.py , Line : 67, Func.Name : getDB, Message : db = mysql.connector.connect(host=host, user=user, password=password, database=database)', 'File : /Users/lql4/opt/anaconda3/lib/python3.9/site-packages/mysql/connector/__init__.py , Line : 273, Func.Name : connect, Message : return MySQLConnection(*args, **kwargs)', 'File : /Users/lql4/opt/anaconda3/lib/python3.9/site-packages/mysql/connector/connection.py , Line : 116, Func.Name : __init__, Message : self.connect(**kwargs)', 'File : /Users/lql4/opt/anaconda3/lib/python3.9/site-packages/mysql/connector/abstracts.py , Line : 1052, Func.Name : connect, Message : self._open_connection()', 'File : /Users/lql4/opt/anaconda3/lib/python3.9/site-packages/mysql/connector/connection.py , Line : 496, Func.Name : _open_connection, Message : self._do_auth(self._user, self._password,', 'File : /Users/lql4/opt/anaconda3/lib/python3.9/site-packages/mysql/connector/connection.py , Line : 242, Func.Name : _do_auth, Message : self._auth_switch_request(username, password)', 'File : /Users/lql4/opt/anaconda3/lib/python3.9/site-packages/mysql/connector/connection.py , Line : 288, Func.Name : _auth_switch_request, Message : raise errors.get_exception(packet)']
sql operation : fail to connect to sql

Exception type : ProgrammingError 
Exception message : 1146 (42S02): Table 'envtestmark2.customers' doesn't exist
Stack trace : ['File : /Users/lql4/PycharmProjects/flaskUtil/util/mysqlUtil.py , Line : 225, Func.Name : insertRows, Message : cursor.executemany(sqlQuery, valueTupleList)', 'File : /Users/lql4/opt/anaconda3/lib/python3.9/site-packages/mysql/connector/cursor.py , Line : 674, Func.Name : executemany, Message : return self.execute(stmt)', 'File : /Users/lql4/opt/anaconda3/lib/python3.9/site-packages/mysql/connector/cursor.py , Line : 572, Func.Name : execute, Message : self._handle_result(self._connection.cmd_query(stmt))', 'File : /Users/lql4/opt/anaconda3/lib/python3.9/site-packages/mysql/connector/connection.py , Line : 922, Func.Name : cmd_query, Message : result = self._handle_result(self._send_cmd(ServerCmd.QUERY, query))', 'File : /Users/lql4/opt/anaconda3/lib/python3.9/site-packages/mysql/connector/connection.py , Line : 732, Func.Name : _handle_result, Message : raise errors.get_exception(packet)']
sql operation : INSERT INTO customers (name, address) VALUES (%s, %s)

Exception type : ProgrammingError 
Exception message : 1064 (42000): You have an error in your SQL syntax; check the manual that corresponds to your MySQL server version for the right syntax to use near ''beckStreetWHERE id = 14' at line 1
Stack trace : ['File : /Users/lql4/PycharmProjects/flaskUtil/util/mysqlUtil.py , Line : 251, Func.Name : dbUpdate, Message : cursor.execute(sqlQuery)', 'File : /Users/lql4/opt/anaconda3/lib/python3.9/site-packages/mysql/connector/cursor.py , Line : 572, Func.Name : execute, Message : self._handle_result(self._connection.cmd_query(stmt))', 'File : /Users/lql4/opt/anaconda3/lib/python3.9/site-packages/mysql/connector/connection.py , Line : 922, Func.Name : cmd_query, Message : result = self._handle_result(self._send_cmd(ServerCmd.QUERY, query))', 'File : /Users/lql4/opt/anaconda3/lib/python3.9/site-packages/mysql/connector/connection.py , Line : 732, Func.Name : _handle_result, Message : raise errors.get_exception(packet)']
sql operation : UPDATE customers SET name = Rance, address = A'beckStreetWHERE id = 14

Exception type : ProgrammingError 
Exception message : 1064 (42000): You have an error in your SQL syntax; check the manual that corresponds to your MySQL server version for the right syntax to use near 'beckStreet'WHERE id = 14' at line 1
Stack trace : ['File : /Users/lql4/PycharmProjects/flaskUtil/util/mysqlUtil.py , Line : 251, Func.Name : dbUpdate, Message : cursor.execute(sqlQuery)', 'File : /Users/lql4/opt/anaconda3/lib/python3.9/site-packages/mysql/connector/cursor.py , Line : 572, Func.Name : execute, Message : self._handle_result(self._connection.cmd_query(stmt))', 'File : /Users/lql4/opt/anaconda3/lib/python3.9/site-packages/mysql/connector/connection.py , Line : 922, Func.Name : cmd_query, Message : result = self._handle_result(self._send_cmd(ServerCmd.QUERY, query))', 'File : /Users/lql4/opt/anaconda3/lib/python3.9/site-packages/mysql/connector/connection.py , Line : 732, Func.Name : _handle_result, Message : raise errors.get_exception(packet)']
sql operation : UPDATE customers SET name = 'Rance', address = 'A'beckStreet'WHERE id = 14

Exception type : ProgrammingError 
Exception message : 1064 (42000): You have an error in your SQL syntax; check the manual that corresponds to your MySQL server version for the right syntax to use near 'beckStreet' WHERE id = 14' at line 1
Stack trace : ['File : /Users/lql4/PycharmProjects/flaskUtil/util/mysqlUtil.py , Line : 251, Func.Name : dbUpdate, Message : cursor.execute(sqlQuery)', 'File : /Users/lql4/opt/anaconda3/lib/python3.9/site-packages/mysql/connector/cursor.py , Line : 572, Func.Name : execute, Message : self._handle_result(self._connection.cmd_query(stmt))', 'File : /Users/lql4/opt/anaconda3/lib/python3.9/site-packages/mysql/connector/connection.py , Line : 922, Func.Name : cmd_query, Message : result = self._handle_result(self._send_cmd(ServerCmd.QUERY, query))', 'File : /Users/lql4/opt/anaconda3/lib/python3.9/site-packages/mysql/connector/connection.py , Line : 732, Func.Name : _handle_result, Message : raise errors.get_exception(packet)']
sql operation : UPDATE customers SET name = 'Rance', address = 'A'beckStreet' WHERE id = 14

